{
  "registryname": "mana_chamber",
  "localizedname": "Mana Chamber",
  "requires-blueprint": true,
  "parts": [
    {
      "x": -1,
      "y": 0,
      "z": 0,
      "elements": [
        "casings_all"
      ]
    },
    {
      "x": -1,
      "y": 0,
      "z": 1,
      "elements": [
        "casings_all"
      ]
    },
    {
      "x": 0,
      "y": 2,
      "z": 2,
      "elements": [
        "minecraft:iron_bars@0"
      ]
    },
    {
      "x": 1,
      "y": 2,
      "z": 1,
      "elements": [
        "minecraft:iron_bars@0"
      ]
    },
    {
      "x": 0,
      "y": 0,
      "z": 1,
      "elements": [
        "minecraft:iron_bars@0"
      ]
    },
    {
      "x": 1,
      "y": 0,
      "z": 0,
      "elements": [
        "casings_all"
      ]
    },
    {
      "x": -1,
      "y": 0,
      "z": 2,
      "elements": [
        "casings_all"
      ]
    },
    {
      "x": 1,
      "y": 2,
      "z": 2,
      "elements": [
        "minecraft:stonebrick@0"
      ]
    },
    {
      "x": 1,
      "y": 0,
      "z": 1,
      "elements": [
        "casings_all"
      ]
    },
    {
      "x": 0,
      "y": 0,
      "z": 2,
      "elements": [
        "casings_all"
      ]
    },
    {
      "x": 1,
      "y": 0,
      "z": 2,
      "elements": [
        "casings_all"
      ]
    },
    {
      "x": 1,
      "y": -1,
      "z": 0,
      "elements": [
        "minecraft:iron_bars@0"
      ]
    },
    {
      "x": 0,
      "y": -1,
      "z": 0,
      "elements": [
        "minecraft:stonebrick@0"
      ]
    },
    {
      "x": -1,
      "y": 1,
      "z": 0,
      "elements": [
        "minecraft:iron_bars@0"
      ]
    },
    {
      "x": -1,
      "y": -1,
      "z": 0,
      "elements": [
        "minecraft:iron_bars@0"
      ]
    },
    {
      "x": 0,
      "y": 1,
      "z": 0,
      "elements": [
        "minecraft:stonebrick@0"
      ]
    },
    {
      "x": -1,
      "y": 1,
      "z": 1,
      "elements": [
        "minecraft:stonebrick@0"
      ]
    },
    {
      "x": 0,
      "y": 1,
      "z": 1,
      "elements": [
        "minecraft:iron_bars@0"
      ]
    },
    {
      "x": 1,
      "y": 1,
      "z": 0,
      "elements": [
        "minecraft:iron_bars@0"
      ]
    },
    {
      "x": -1,
      "y": 1,
      "z": 2,
      "elements": [
        "minecraft:iron_bars@0"
      ]
    },
    {
      "x": 0,
      "y": 1,
      "z": 2,
      "elements": [
        "minecraft:stonebrick@0"
      ]
    },
    {
      "x": 1,
      "y": 1,
      "z": 1,
      "elements": [
        "minecraft:stonebrick@0"
      ]
    },
    {
      "x": -1,
      "y": -1,
      "z": 1,
      "elements": [
        "minecraft:stonebrick@0"
      ]
    },
    {
      "x": 1,
      "y": 1,
      "z": 2,
      "elements": [
        "minecraft:iron_bars@0"
      ]
    },
    {
      "x": 0,
      "y": -1,
      "z": 1,
      "elements": [
        "minecraft:stonebrick@0"
      ]
    },
    {
      "x": -1,
      "y": -1,
      "z": 2,
      "elements": [
        "minecraft:iron_bars@0"
      ]
    },
    {
      "x": 0,
      "y": -1,
      "z": 2,
      "elements": [
        "minecraft:stonebrick@0"
      ]
    },
    {
      "x": 1,
      "y": -1,
      "z": 1,
      "elements": [
        "minecraft:stonebrick@0"
      ]
    },
    {
      "x": 1,
      "y": -1,
      "z": 2,
      "elements": [
        "minecraft:iron_bars@0"
      ]
    },
    {
      "x": -1,
      "y": 2,
      "z": 0,
      "elements": [
        "minecraft:stonebrick@0"
      ]
    },
    {
      "x": -1,
      "y": 2,
      "z": 1,
      "elements": [
        "minecraft:iron_bars@0"
      ]
    },
    {
      "x": 0,
      "y": 2,
      "z": 0,
      "elements": [
        "minecraft:iron_bars@0"
      ]
    },
    {
      "x": -1,
      "y": 2,
      "z": 2,
      "elements": [
        "minecraft:stonebrick@0"
      ]
    },
    {
      "x": 0,
      "y": 2,
      "z": 1,
      "elements": [
        "minecraft:stonebrick@0"
      ]
    },
    {
      "x": 1,
      "y": 2,
      "z": 0,
      "elements": [
        "minecraft:stonebrick@0"
      ]
    }
  ]
}